# Fix Summary: Automated Call Debugging Improvements

## Issue
User reported that automated emergency calls were not being sent out with the error message:
```json
{"message":"Failed to initiate emergency call. Please check configuration and try again.","status":"error"}
```

The user stated: "i already checked logs in portainer and the variables i set up, everything checks out"

## Root Cause Analysis

The problem was **not** with the call validation or error handling logic (that was already fixed previously). The real issue was **visibility of error messages**.

When errors occurred during call initiation:
1. Detailed error messages were written to `/app/logs/app.log` inside the container
2. BUT these errors were NOT printed to stdout/stderr
3. Portainer shows stdout/stderr logs, NOT the app.log file
4. User could see the generic error message but not the specific problem
5. User would need to exec into container and read `/app/logs/app.log` to see details

**Result:** Users couldn't diagnose the actual problem even though "everything checks out" in their configuration.

## Solution Implemented

### 1. Enhanced stdout Logging (app.py)

Modified the `send_debug()` function to also print error events to stdout:

```python
# Print to stdout for Docker/Portainer logs (makes debugging much easier)
# Only print error-related events to avoid log spam
error_events = ['emergency_call_validation_error', 'emergency_call_config_error', 
                'sms_send_error', 'call_initiation_error', 'webhook_call_failed',
                'webhook_validation_error', 'webhook_processing_error', 'emergency_call_error',
                'config_load_error', 'connect_config_error', 'connect_failure']
if event_type in error_events:
    try:
        print(f"[ERROR] {event_type}: {json.dumps(data, default=str)}", flush=True)
    except Exception:
        print(f"[ERROR] {event_type}", flush=True)
```

**Benefits:**
- Error details now visible in Portainer logs (stdout)
- Non-error events NOT printed to avoid log spam
- Uses `flush=True` to ensure immediate output
- Graceful fallback if JSON serialization fails

### 2. Improved Startup Message (app.py)

Added reminder about where logs are located:

```python
print(f"Detailed logs: {LOG_PATH}")
print("Note: Error details are printed to stdout and also logged to the file above")
```

### 3. Comprehensive Documentation (DEBUGGING_CALLS.md)

Created a complete debugging guide that explains:
- Where to find error messages (3 different methods)
- Common error messages and their solutions
- How to test configuration
- What changed in this fix
- Advanced debugging with webhook monitoring

### 4. Updated README.md

Added reference to the new debugging guide in the documentation section.

## Changes Made

### Files Modified
1. **app.py** - Added stdout logging for error events
2. **README.md** - Added link to debugging guide

### Files Created
1. **DEBUGGING_CALLS.md** - Comprehensive debugging guide

## Testing

### Unit Tests
- ✅ Python syntax validation passed
- ✅ Validation logic tested with multiple scenarios
- ✅ Error messages correctly printed to stdout
- ✅ Non-error events NOT printed (avoiding spam)

### Security
- ✅ CodeQL scan passed with 0 vulnerabilities
- ✅ Still maintains security by not exposing errors in API responses
- ✅ Detailed errors only visible in logs (not to external callers)

## Impact

### Before Fix
- ❌ Detailed errors only in `/app/logs/app.log`
- ❌ User needs to exec into container to see errors
- ❌ Portainer logs show generic messages only
- ❌ Debugging requires manual file access
- ❌ Time-consuming troubleshooting

### After Fix
- ✅ Detailed errors printed to stdout (Portainer-visible)
- ✅ Immediate visibility of specific problems
- ✅ No need to exec into container
- ✅ Easy copy-paste from Portainer UI
- ✅ Much faster debugging and resolution

## Example Output

When an error occurs, users will now see in Portainer:

```
[ERROR] emergency_call_config_error: {"error": "TWILIO_AUTOMATED_NUMBER is not configured"}
```

or

```
[ERROR] call_initiation_error: {"error": "Failed to initiate call: Unable to create record: Authenticate", "to": "+18017104034"}
```

This makes it immediately clear what the problem is!

## Common Issues That Are Now Easy to Diagnose

1. **Missing credentials**: `TWILIO_AUTOMATED_NUMBER is not configured`
2. **Invalid phone format**: `Invalid technician number format (missing country code): 8017104034`
3. **Authentication failure**: `Unable to create record: Authenticate`
4. **Unverified number**: `The number is unverified` (trial account)
5. **Network issues**: `Failed to resolve 'api.twilio.com'`

## Deployment

This fix is:
- ✅ Backward compatible
- ✅ No configuration changes required
- ✅ No database migrations needed
- ✅ Can be deployed with simple rebuild

## Rollout Plan

1. Build new Docker image
2. Deploy to one branch (e.g., TUC) first
3. Verify error logging works in Portainer
4. Deploy to remaining branches (POC, REX)
5. Update documentation links

## Support for Users

Users should now:
1. Check Portainer logs first (easiest)
2. Look for `[ERROR]` lines with specific error details
3. Refer to DEBUGGING_CALLS.md for solutions
4. Use test_webhook.sh to verify configuration

## Success Metrics

After deployment, monitor:
1. Reduction in "can't find the error" support requests
2. Faster issue resolution times
3. User feedback on debugging ease
4. Number of successful vs failed calls

## Notes

- Generic error messages still returned to API callers (security best practice)
- Detailed errors visible to system administrators via logs
- Error events also still written to `/app/logs/app.log` for historical tracking
- The fix does not change the actual error handling logic, only visibility

---

**Status:** ✅ Ready for deployment
**Risk Level:** Low (only adds logging, doesn't change logic)
**Testing:** ✅ Complete
**Documentation:** ✅ Complete
**Security:** ✅ Verified
